Workbook

Sheet Perf Overview + Raster Summary
A1: Test Number | B1: Method | C1: Cost | D1: Input Token | E1: Output Token | F1: Latency | G1: Building | H1: Floor | I1: API Calls | J1: Labels | K1: Type | L1: Notes
A2: 1.1 | B2: Bitmap | C2: N/A | F2: 74.62 | G2: Snowden Towers | H2: L2 | I2: N/A | J2: 62 | K2: Commercial Office | L2: *Implementation is not good
A3: 1.2 | B3: SA | C3: N/A | F3: 8.13 | G3: Snowden Towers | H3: L2 | I3: N/A | J3: 70 | K3: Commercial Office | L3: *150K iterations using a pre-computed summed-area table
A4: 1.3 | B4: LLM-VBP | C4: 0.23 | D4: 25519 | E4: 4122 | F4: 35.387 | G4: Snowden Towers | H4: L2 | I4: 3 | J4: 70 | K4: Commercial Office
A5: 1.4 | B5: LLM-VSP | C5: 0.55 | D5: 98770 | E5: 17920 | F5: 77 | G5: Snowden Towers | H5: L2 | I5: 70 | J5: 70 | K5: Commercial Office | L5: *Data is extrapolated from the average of 24 API calls, results were rate limited. Input 1411, Output 256
A6: 1.5 | B6: LLM-DEP | C6: 0.26 | D6: 47311 | E6: 947 | F6: 10.792 | G6: Snowden Towers | H6: L2 | I6: 1 | J6: 69 | K6: Commercial Office
A7: 2.1 | B7: LLM-DEP | C7: 0.26 | D7: 46611 | E7: 1132 | F7: 15.851 | G7: Snowden Towers | H7: L1 | I7: 1 | J7: 85 | K7: Commercial Office
A8: 2.2 | B8: LLM-DEP | C8: 0.19 | D8: 34810 | E8: 649 | F8: 8.093 | G8: REVIT RAC Advanced Sample Project 2018 | H8: L1 | I8: 1 | J8: 77 | K8: Commercial Office
A9: 2.3 | B9: LLM-DEP | C9: 0.13 | D9: 26238 | E9: 201 | F9: 3.084 | G9: REVIT RAC Basic Sample Project 2018 | H9: L1 | I9: 1 | J9: 19 | K9: Residential House (Small) | L9: https://bim-design.com/library/jp-contents/
A10: 2.4 | B10: LLM-DEP | C10: 0.15 | D10: 27172 | E10: 285 | F10: 3.629 | G10: REVIT RAC Basic Sample Project 2018 | H10: L2 | I10: 1 | J10: 26 | K10: Residential House (Small) | L10: https://help.autodesk.com/view/RVT/2024/ENU/?guid=GUID-61EF2F22-3A1F-4317-B925-1E85F138BE88
A11: 2.5 | B11: LLM-DEP | C11: 0.23 | D11: 46611 | E11: 1132 | F11: 15.851 | G11: REVIT RAC Japan Sample Project 2020 (ver 1.7) | H11: L7 | I11: 1 | J11: 111 | K11: Commercial Office | L11: *Poor placement due to unique tag types, need adjustment. Drafting conventions are broadly similar
A12: 2.6 | B12: LLM-DEP | C12: 0.17 | D12: 32550 | E12: 330 | F12: 4.291 | G12: REVIT RAC Germany Sample Project 2019 (DACH Studio) | H12: L1 (EG) | I12: 1 | J12: 36 | K12: Studio Office | L12: *German/DACH Studio drafting standards have no border around tags, thus bounding boxes are not representative of tag area.
A13: 3 | B13: LLM-DEP-TOT | F13: =SUM(F6:F12) -> 61.591 | J13: =SUM(J6:J12) -> 423
A15: Version 1 Tests
A16: 1.1 | B16: Bitmap | C16: QTY | D16: Dist_From_Centre | F16: Dist_From_Optimal | H16: Optimal_Dist_From_Centre
D17: Mean | E17: Median | F17: Mean | G17: Median | H17: Mean | I17: Median | O17: Per label latency (ms)
B18: All Tags | C18: 62 | D18: N/A | E18: N/A | F18: 36.988796 | G18: 38.183766 | H18: N/A | I18: N/A | L18: =F18/38 -> 0.97338936 | N18: Bitmap | O18: =P18*1000 -> 1203.5484 | P18: =F2/J2 -> 1.2035484
B19: Door Tags | C19: 13 | D19: N/A | E19: N/A | F19: 52.891453 | G19: 33.941125 | H19: N/A | I19: N/A | L19: =F19/38 -> 1.3918803 | N19: SA | O19: =P19*1000 -> 116.14286 | P19: =F3/J3 -> 0.11614286
B20: Window Tags | C20: 16 | D20: N/A | E20: N/A | F20: 39.702877 | G20: 38.183766 | H20: N/A | I20: N/A | L20: =F20/38 -> 1.0448125 | N20: LLM-VBP | O20: =P20*1000 -> 505.52857 | P20: =F4/J4 -> 0.50552857
B21: Wall Tags | C21: 24 | D21: N/A | E21: N/A | F21: 30.983439 | G21: 16.263456 | H21: N/A | I21: N/A | L21: =F21/38 -> 0.81535366 | N21: LLM-VSP | O21: =P21*1000 -> 1100 | P21: =F5/J5 -> 1.1
B22: Room Tags | C22: 9 | D22: N/A | E22: N/A | F22: 25.207543 | G22: 0 | H22: N/A | I22: N/A | L22: =F22/38 -> 0.66335638 | N22: LLM-DEP | O22: =P22*1000 -> 145.6052 | P22: =F13/J13 -> 0.1456052
L23: =F23/38 -> 0
A24: 1.2 | B24: SA | C24: QTY | D24: Dist_From_Centre | F24: Dist_From_Optimal | H24: Optimal_Dist_From_Centre | L24: =F24/38 -> #VALUE!
D25: Mean | E25: Median | F25: Mean | G25: Median | H25: Mean | I25: Median | L25: =F25/38 -> #VALUE!
B26: All Tags | C26: 70 | D26: N/A | E26: N/A | F26: 65.686509 | G26: 53.786608 | H26: N/A | I26: N/A | L26: =F26/38 -> 1.7285923
B27: Door Tags | C27: 15 | D27: N/A | E27: N/A | F27: 72.581813 | G27: 69.46222 | H27: N/A | I27: N/A | L27: =F27/38 -> 1.9100477
B28: Window Tags | C28: 17 | D28: N/A | E28: N/A | F28: 38.002334 | G28: 40.853396 | H28: N/A | I28: N/A | L28: =F28/38 -> 1.0000614
B29: Wall Tags | C29: 26 | D29: N/A | E29: N/A | F29: 73.590237 | G29: 54.179571 | H29: N/A | I29: N/A | L29: =F29/38 -> 1.9365852
B30: Room Tags | C30: 12 | D30: N/A | E30: N/A | F30: 79.161882 | G30: 98.70607 | H30: N/A | I30: N/A | L30: =F30/38 -> 2.0832074
L31: =F31/38 -> 0
A32: 1.3 | B32: LLM-VBP | C32: QTY | D32: Dist_From_Centre | F32: Dist_From_Optimal | H32: Optimal_Dist_From_Centre | L32: =F32/38 -> #VALUE!
D33: Mean | E33: Median | F33: Mean | G33: Median | H33: Mean | I33: Median | J33: Confidence | L33: =F33/38 -> #VALUE!
B34: All Tags | C34: 70 | D34: N/A | E34: N/A | F34: 13.824254 | G34: 2.236068 | H34: N/A | I34: N/A | J34: 0.83142857 | L34: =F34/38 -> 0.36379617
B35: Door Tags | C35: 15 | D35: N/A | E35: N/A | F35: 0.81617605 | G35: 1 | H35: N/A | I35: N/A | J35: 0.80333333 | L35: =F35/38 -> 0.021478317
B36: Window Tags | C36: 17 | D36: N/A | E36: N/A | F36: 37.766046 | G36: 2.8284271 | H36: N/A | I36: N/A | J36: 0.87058824 | L36: =F36/38 -> 0.99384331
B37: Wall Tags | C37: 26 | D37: N/A | E37: N/A | F37: 7.0294357 | G37: 2.236068 | H37: N/A | I37: N/A | J37: 0.83076923 | L37: =F37/38 -> 0.18498515
B38: Room Tags | C38: 12 | D38: N/A | E38: N/A | F38: 10.888921 | G38: 1.2071068 | H38: N/A | I38: N/A | J38: 0.8125 | L38: =F38/38 -> 0.28655056
A40: 1.4 | B40: LLM-VSP | C40: QTY | D40: Dist_From_Centre | F40: Dist_From_Optimal | H40: Optimal_Dist_From_Centre
D41: Mean | E41: Median | F41: Mean | G41: Median | H41: Mean | I41: Median | J41: Confidence
B42: All Tags | C42: 70 | D42: N/A | E42: N/A | F42: 17.777778 | G42: 0 | H42: N/A | I42: N/A | J42: 0.88111111 | L42: =F42/38 -> 0.46783626
...

Sheet Combined Summary
A1: COMBINED RESULTS — ALL FLOORPLANS
A4: Scope | B4: Quantity | C4: Mean Dist_From_Optimal | D4: Median Dist_From_Optimal | E4: RMSE Dist_From_Optimal | F4: Win Rate | G4: Mean Error Reduction | H4: Mean Cosine Similarity | I4: Mean Solver-vs- Human Ratio | J4: % Further Than Human | K4: Gross Failures | L4: 95th Pct Dist_From_Optimal
A5: ALL TAGS — ALL FLOORPLANS | B5: =COUNTA('Basic L1'!$B$2:$B$20)+COUNTA('Basic L2'!$B$2:$B$27)+COUNTA('Advanced L1'!$B$2:$B$78)+COUNTA('Germany L1'!$B$2:$B$37)+COUNTA('Japan L7'!$B$2:$B$112)+COUNTA('Snowden Tower L1'!$B$2:$B$86)+COUNTA('Snowden Tower L2'!$B$2:$B$70) -> 423 | C5: =IF((COUNT('Basic L1'!$K$2:$K$20)+COUNT('Basic L2'!$K$2:$K$27)+COUNT('Advanced L1'!$K$2:$K$78)+COUNT('Germany L1'!$K$2:$K$37)+COUNT('Japan L7'!$K$2:$K$112)+COUNT('Snowden Tower L1'!$K$2:$K$86)+COUNT('Snowden Tower L2'!$K$2:$K$70))=0,"N/A",(SUM('Basic L1'!$K$2:$K$20)+SUM('Basic L2'!$K$2:$K$27)+SUM('Advanced L1'!$K$2:$K$78)+SUM('Germany L1'!$K$2:$K$37)+SUM('Japan L7'!$K$2:$K$112)+SUM('Snowden Tower L1'!$K$2:$K$86)+SUM('Snowden Tower L2'!$K$2:$K$70))/(COUNT('Basic L1'!$K$2:$K$20)+COUNT('Basic L2'!$K$2:$K$27)+COUNT('Advanced L1'!$K$2:$K$78)+COUNT('Germany L1'!$K$2:$K$37)+COUNT('Japan L7'!$K$2:$K$112)+COUNT('Snowden Tower L1'!$K$2:$K$86)+COUNT('Snowden Tower L2'!$K$2:$K$70))) -> 4.1928495 | D5: =IFERROR(MEDIAN('Basic L1'!$K$2:$K$20,'Basic L2'!$K$2:$K$27,'Advanced L1'!$K$2:$K$78,'Germany L1'!$K$2:$K$37,'Japan L7'!$K$2:$K$112,'Snowden Tower L1'!$K$2:$K$86,'Snowden Tower L2'!$K$2:$K$70),"N/A") -> 1.4886 | E5: =IF((COUNT('Basic L1'!$K$2:$K$20)+COUNT('Basic L2'!$K$2:$K$27)+COUNT('Advanced L1'!$K$2:$K$78)+COUNT('Germany L1'!$K$2:$K$37)+COUNT('Japan L7'!$K$2:$K$112)+COUNT('Snowden Tower L1'!$K$2:$K$86)+COUNT('Snowden Tower L2'!$K$2:$K$70))=0,"N/A",SQRT((SUMSQ('Basic L1'!$K$2:$K$20)+SUMSQ('Basic L2'!$K$2:$K$27)+SUMSQ('Advanced L1'!$K$2:$K$78)+SUMSQ('Germany L1'!$K$2:$K$37)+SUMSQ('Japan L7'!$K$2:$K$112)+SUMSQ('Snowden Tower L1'!$K$2:$K$86)+SUMSQ('Snowden Tower L2'!$K$2:$K$70))/(COUNT('Basic L1'!$K$2:$K$20)+COUNT('Basic L2'!$K$2:$K$27)+COUNT('Advanced L1'!$K$2:$K$78)+COUNT('Germany L1'!$K$2:$K$37)+COUNT('Japan L7'!$K$2:$K$112)+COUNT('Snowden Tower L1'!$K$2:$K$86)+COUNT('Snowden Tower L2'!$K$2:$K$70)))) -> 11.280784 | F5: =IF((COUNT('Basic L1'!$R$2:$R$20)+COUNT('Basic L2'!$R$2:$R$27)+COUNT('Advanced L1'!$R$2:$R$78)+COUNT('Germany L1'!$R$2:$R$37)+COUNT('Japan L7'!$R$2:$R$112)+COUNT('Snowden Tower L1'!$R$2:$R$86)+COUNT('Snowden Tower L2'!$R$2:$R$70))=0,"N/A",(COUNTIF('Basic L1'!$R$2:$R$20,1)+COUNTIF('Basic L2'!$R$2:$R$27,1)+COUNTIF('Advanced L1'!$R$2:$R$78,1)+COUNTIF('Germany L1'!$R$2:$R$37,1)+COUNTIF('Japan L7'!$R$2:$R$112,1)+COUNTIF('Snowden Tower L1'!$R$2:$R$86,1)+COUNTIF('Snowden Tower L2'!$R$2:$R$70,1))/(COUNT('Basic L1'!$R$2:$R$20)+COUNT('Basic L2'!$R$2:$R$27)+COUNT('Advanced L1'!$R$2:$R$78)+COUNT('Germany L1'!$R$2:$R$37)+COUNT('Japan L7'!$R$2:$R$112)+COUNT('Snowden Tower L1'!$R$2:$R$86)+COUNT('Snowden Tower L2'!$R$2:$R$70))) -> 0.6503856 | G5: =IF((COUNT('Basic L1'!$N$2:$N$20)+COUNT('Basic L2'!$N$2:$N$27)+COUNT('Advanced L1'!$N$2:$N$78)+COUNT('Germany L1'!$N$2:$N$37)+COUNT('Japan L7'!$N$2:$N$112)+COUNT('Snowden Tower L1'!$N$2:$N$86)+COUNT('Snowden Tower L2'!$N$2:$N$70))=0,"N/A",(SUM('Basic L1'!$N$2:$N$20)+SUM('Basic L2'!$N$2:$N$27)+SUM('Advanced L1'!$N$2:$N$78)+SUM('Germany L1'!$N$2:$N$37)+SUM('Japan L7'!$N$2:$N$112)+SUM('Snowden Tower L1'!$N$2:$N$86)+SUM('Snowden Tower L2'!$N$2:$N$70))/(COUNT('Basic L1'!$N$2:$N$20)+COUNT('Basic L2'!$N$2:$N$27)+COUNT('Advanced L1'!$N$2:$N$78)+COUNT('Germany L1'!$N$2:$N$37)+COUNT('Japan L7'!$N$2:$N$112)+COUNT('Snowden Tower L1'!$N$2:$N$86)+COUNT('Snowden Tower L2'!$N$2:$N$70))) -> -2.3968969 | H5: =IF((COUNT('Basic L1'!$O$2:$O$20)+COUNT('Basic L2'!$O$2:$O$27)+COUNT('Advanced L1'!$O$2:$O$78)+COUNT('Germany L1'!$O$2:$O$37)+COUNT('Japan L7'!$O$2:$O$112)+COUNT('Snowden Tower L1'!$O$2:$O$86)+COUNT('Snowden Tower L2'!$O$2:$O$70))=0,"N/A",(SUM('Basic L1'!$O$2:$O$20)+SUM('Basic L2'!$O$2:$O$27)+SUM('Advanced L1'!$O$2:$O$78)+SUM('Germany L1'!$O$2:$O$37)+SUM('Japan L7'!$O$2:$O$112)+SUM('Snowden Tower L1'!$O$2:$O$86)+SUM('Snowden Tower L2'!$O$2:$O$70))/(COUNT('Basic L1'!$O$2:$O$20)+COUNT('Basic L2'!$O$2:$O$27)+COUNT('Advanced L1'!$O$2:$O$78)+COUNT('Germany L1'!$O$2:$O$37)+COUNT('Japan L7'!$O$2:$O$112)+COUNT('Snowden Tower L1'!$O$2:$O$86)+COUNT('Snowden Tower L2'!$O$2:$O$70))) -> 0.58963511 | I5: =IF((COUNT('Basic L1'!$S$2:$S$20)+COUNT('Basic L2'!$S$2:$S$27)+COUNT('Advanced L1'!$S$2:$S$78)+COUNT('Germany L1'!$S$2:$S$37)+COUNT('Japan L7'!$S$2:$S$112)+COUNT('Snowden Tower L1'!$S$2:$S$86)+COUNT('Snowden Tower L2'!$S$2:$S$70))=0,"N/A",(SUM('Basic L1'!$S$2:$S$20)+SUM('Basic L2'!$S$2:$S$27)+SUM('Advanced L1'!$S$2:$S$78)+SUM('Germany L1'!$S$2:$S$37)+SUM('Japan L7'!$S$2:$S$112)+SUM('Snowden Tower L1'!$S$2:$S$86)+SUM('Snowden Tower L2'!$S$2:$S$70))/(COUNT('Basic L1'!$S$2:$S$20)+COUNT('Basic L2'!$S$2:$S$27)+COUNT('Advanced L1'!$S$2:$S$78)+COUNT('Germany L1'!$S$2:$S$37)+COUNT('Japan L7'!$S$2:$S$112)+COUNT('Snowden Tower L1'!$S$2:$S$86)+COUNT('Snowden Tower L2'!$S$2:$S$70))) -> 3.7541516 | J5: =IF((COUNT('Basic L1'!$S$2:$S$20)+COUNT('Basic L2'!$S$2:$S$27)+COUNT('Advanced L1'!$S$2:$S$78)+COUNT('Germany L1'!$S$2:$S$37)+COUNT('Japan L7'!$S$2:$S$112)+COUNT('Snowden Tower L1'!$S$2:$S$86)+COUNT('Snowden Tower L2'!$S$2:$S$70))=0,"N/A",(COUNTIF('Basic L1'!$S$2:$S$20,">1")+COUNTIF('Basic L2'!$S$2:$S$27,">1")+COUNTIF('Advanced L1'!$S$2:$S$78,">1")+COUNTIF('Germany L1'!$S$2:$S$37,">1")+COUNTIF('Japan L7'!$S$2:$S$112,">1")+COUNTIF('Snowden Tower L1'!$S$2:$S$86,">1")+COUNTIF('Snowden Tower L2'!$S$2:$S$70,">1"))/(COUNT('Basic L1'!$S$2:$S$20)+COUNT('Basic L2'!$S$2:$S$27)+COUNT('Advanced L1'!$S$2:$S$78)+COUNT('Germany L1'!$S$2:$S$37)+COUNT('Japan L7'!$S$2:$S$112)+COUNT('Snowden Tower L1'!$S$2:$S$86)+COUNT('Snowden Tower L2'!$S$2:$S$70))) -> 0.57069409 | K5: =COUNTIF('Basic L1'!$K$2:$K$20,">15.0")+COUNTIF('Basic L2'!$K$2:$K$27,">15.0")+COUNTIF('Advanced L1'!$K$2:$K$78,">15.0")+COUNTIF('Germany L1'!$K$2:$K$37,">15.0")+COUNTIF('Japan L7'!$K$2:$K$112,">15.0")+COUNTIF('Snowden Tower L1'!$K$2:$K$86,">15.0")+COUNTIF('Snowden Tower L2'!$K$2:$K$70,">15.0") -> 24 | L5: 19.4885
A6: Door Tags | B6: =COUNTIF('Basic L1'!$B$2:$B$20,"Doors")+COUNTIF('Basic L2'!$B$2:$B$27,"Doors")+COUNTIF('Advanced L1'!$B$2:$B$78,"Doors")+COUNTIF('Germany L1'!$B$2:$B$37,"Doors")+COUNTIF('Japan L7'!$B$2:$B$112,"Doors")+COUNTIF('Snowden Tower L1'!$B$2:$B$86,"Doors")+COUNTIF('Snowden Tower L2'!$B$2:$B$70,"Doors") -> 116 | C6: =IF((COUNTIFS('Basic L1'!$B$2:$B$20,"Doors",'Basic L1'!$K$2:$K$20,"<>")+COUNTIFS('Basic L2'!$B$2:$B$27,"Doors",'Basic L2'!$K$2:$K$27,"<>")+COUNTIFS('Advanced L1'!$B$2:$B$78,"Doors",'Advanced L1'!$K$2:$K$78,"<>")+COUNTIFS('Germany L1'!$B$2:$B$37,"Doors",'Germany L1'!$K$2:$K$37,"<>")+COUNTIFS('Japan L7'!$B$2:$B$112,"Doors",'Japan L7'!$K$2:$K$112,"<>")+COUNTIFS('Snowden Tower L1'!$B$2:$B$86,"Doors",'Snowden Tower L1'!$K$2:$K$86,"<>")+COUNTIFS('Snowden Tower L2'!$B$2:$B$70,"Doors",'Snowden Tower L2'!$K$2:$K$70,"<>"))=0,"N/A",(SUMIF('Basic L1'!$B$2:$B$20,"Doors",'Basic L1'!$K$2:$K$20)+SUMIF('Basic L2'!$B$2:$B$27,"Doors",'Basic L2'!$K$2:$K$27)+SUMIF('Advanced L1'!$B$2:$B$78,"Doors",'Advanced L1'!$K$2:$K$78)+SUMIF('Germany L1'!$B$2:$B$37,"Doors",'Germany L1'!$K$2:$K$37)+SUMIF('Japan L7'!$B$2:$B$112,"Doors",'Japan L7'!$K$2:$K$112)+SUMIF('Snowden Tower L1'!$B$2:$B$86,"Doors",'Snowden Tower L1'!$K$2:$K$86)+SUMIF('Snowden Tower L2'!$B$2:$B$70,"Doors",'Snowden Tower L2'!$K$2:$K$70))/(COUNTIFS('Basic L1'!$B$2:$B$20,"Doors",'Basic L1'!$K$2:$K$20,"<>")+COUNTIFS('Basic L2'!$B$2:$B$27,"Doors",'Basic L2'!$K$2:$K$27,"<>")+COUNTIFS('Advanced L1'!$B$2:$B$78,"Doors",'Advanced L1'!$K$2:$K$78,"<>")+COUNTIFS('Germany L1'!$B$2:$B$37,"Doors",'Germany L1'!$K$2:$K$37,"<>")+COUNTIFS('Japan L7'!$B$2:$B$112,"Doors",'Japan L7'!$K$2:$K$112,"<>")+COUNTIFS('Snowden Tower L1'!$B$2:$B$86,"Doors",'Snowden Tower L1'!$K$2:$K$86,"<>")+COUNTIFS('Snowden Tower L2'!$B$2:$B$70,"Doors",'Snowden Tower L2'!$K$2:$K$70,"<>"))) -> 6.609086 | D6: {=IFERROR(MEDIAN(IF('Basic L1'!$B$2:$B$20="Doors",'Basic L1'!$K$2:$K$20),IF('Basic L2'!$B$2:$B$27="Doors",'Basic L2'!$K$2:$K$27),IF('Advanced L1'!$B$2:$B$78="Doors",'Advanced L1'!$K$2:$K$78),IF('Germany L1'!$B$2:$B$37="Doors",'Germany L1'!$K$2:$K$37),IF('Japan L7'!$B$2:$B$112="Doors",'Japan L7'!$K$2:$K$112),IF('Snowden Tower L1'!$B$2:$B$86="Doors",'Snowden Tower L1'!$K$2:$K$86),IF('Snowden Tower L2'!$B$2:$B$70="Doors",'Snowden Tower L2'!$K$2:$K$70)),"N/A")} -> 1.3092 | E6: =IF((COUNTIFS('Basic L1'!$B$2:$B$20,"Doors",'Basic L1'!$K$2:$K$20,"<>")+COUNTIFS('Basic L2'!$B$2:$B$27,"Doors",'Basic L2'!$K$2:$K$27,"<>")+COUNTIFS('Advanced L1'!$B$2:$B$78,"Doors",'Advanced L1'!$K$2:$K$78,"<>")+COUNTIFS('Germany L1'!$B$2:$B$37,"Doors",'Germany L1'!$K$2:$K$37,"<>")+COUNTIFS('Japan L7'!$B$2:$B$112,"Doors",'Japan L7'!$K$2:$K$112,"<>")+COUNTIFS('Snowden Tower L1'!$B$2:$B$86,"Doors",'Snowden Tower L1'!$K$2:$K$86,"<>")+COUNTIFS('Snowden Tower L2'!$B$2:$B$70,"Doors",'Snowden Tower L2'!$K$2:$K$70,"<>"))=0,"N/A",SQRT((SUMPRODUCT(('Basic L1'!$B$2:$B$20="Doors")*('Basic L1'!$K$2:$K$20)*('Basic L1'!$K$2:$K$20))+SUMPRODUCT(('Basic L2'!$B$2:$B$27="Doors")*('Basic L2'!$K$2:$K$27)*('Basic L2'!$K$2:$K$27))+SUMPRODUCT(('Advanced L1'!$B$2:$B$78="Doors")*('Advanced L1'!$K$2:$K$78)*('Advanced L1'!$K$2:$K$78))+SUMPRODUCT(('Germany L1'!$B$2:$B$37="Doors")*('Germany L1'!$K$2:$K$37)*('Germany L1'!$K$2:$K$37))+SUMPRODUCT(('Japan L7'!$B$2:$B$112="Doors")*('Japan L7'!$K$2:$K$112)*('Japan L7'!$K$2:$K$112))+SUMPRODUCT(('Snowden Tower L1'!$B$2:$B$86="Doors")*('Snowden Tower L1'!$K$2:$K$86)*('Snowden Tower L1'!$K$2:$K$86))+SUMPRODUCT(('Snowden Tower L2'!$B$2:$B$70="Doors")*('Snowden Tower L2'!$K$2:$K$70)*('Snowden Tower L2'!$K$2:$K$70)))/(COUNTIFS('Basic L1'!$B$2:$B$20,"Doors",'Basic L1'!$K$2:$K$20,"<>")+COUNTIFS('Basic L2'!$B$2:$B$27,"Doors",'Basic L2'!$K$2:$K$27,"<>")+COUNTIFS('Advanced L1'!$B$2:$B$78,"Doors",'Advanced L1'!$K$2:$K$78,"<>")+COUNTIFS('Germany L1'!$B$2:$B$37,"Doors",'Germany L1'!$K$2:$K$37,"<>")+COUNTIFS('Japan L7'!$B$2:$B$112,"Doors",'Japan L7'!$K$2:$K$112,"<>")+COUNTIFS('Snowden Tower L1'!$B$2:$B$86,"Doors",'Snowden Tower L1'!$K$2:$K$86,"<>")+COUNTIFS('Snowden Tower L2'!$B$2:$B$70,"Doors",'Snowden Tower L2'!$K$2:$K$70,"<>")))) -> 16.896493 | F6: =IF((COUNTIFS('Basic L1'!$B$2:$B$20,"Doors",'Basic L1'!$R$2:$R$20,"<>")+COUNTIFS('Basic L2'!$B$2:$B$27,"Doors",'Basic L2'!$R$2:$R$27,"<>")+COUNTIFS('Advanced L1'!$B$2:$B$78,"Doors",'Advanced L1'!$R$2:$R$78,"<>")+COUNTIFS('Germany L1'!$B$2:$B$37,"Doors",'Germany L1'!$R$2:$R$37,"<>")+COUNTIFS('Japan L7'!$B$2:$B$112,"Doors",'Japan L7'!$R$2:$R$112,"<>")+COUNTIFS('Snowden Tower L1'!$B$2:$B$86,"Doors",'Snowden Tower L1'!$R$2:$R$86,"<>")+COUNTIFS('Snowden Tower L2'!$B$2:$B$70,"Doors",'Snowden Tower L2'!$R$2:$R$70,"<>"))=0,"N/A",(SUMIFS('Basic L1'!$R$2:$R$20,'Basic L1'!$B$2:$B$20,"Doors")+SUMIFS('Basic L2'!$R$2:$R$27,'Basic L2'!$B$2:$B$27,"Doors")+SUMIFS('Advanced L1'!$R$2:$R$78,'Advanced L1'!$B$2:$B$78,"Doors")+SUMIFS('Germany L1'!$R$2:$R$37,'Germany L1'!$B$2:$B$37,"Doors")+SUMIFS('Japan L7'!$R$2:$R$112,'Japan L7'!$B$2:$B$112,"Doors")+SUMIFS('Snowden Tower L1'!$R$2:$R$86,'Snowden Tower L1'!$B$2:$B$86,"Doors")+SUMIFS('Snowden Tower L2'!$R$2:$R$70,'Snowden Tower L2'!$B$2:$B$70,"Doors"))/(COUNTIFS('Basic L1'!$B$2:$B$20,"Doors",'Basic L1'!$R$2:$R$20,"<>")+COUNTIFS('Basic L2'!$B$2:$B$27,"Doors",'Basic L2'!$R$2:$R$27,"<>")+COUNTIFS('Advanced L1'!$B$2:$B$78,"Doors",'Advanced L1'!$R$2:$R$78,"<>")+COUNTIFS('Germany L1'!$B$2:$B$37,"Doors",'Germany L1'!$R$2:$R$37,"<>")+COUNTIFS('Japan L7'!$B$2:$B$112,"Doors",'Japan L7'!$R$2:$R$112,"<>")+COUNTIFS('Snowden Tower L1'!$B$2:$B$86,"Doors",'Snowden Tower L1'!$R$2:$R$86,"<>")+COUNTIFS('Snowden Tower L2'!$B$2:$B$70,"Doors",'Snowden Tower L2'!$R$2:$R$70,"<>"))) -> 0.5862069 | G6: =IF((COUNTIFS('Basic L1'!$B$2:$B$20,"Doors",'Basic L1'!$N$2:$N$20,"<>")+COUNTIFS('Basic L2'!$B$2:$B$27,"Doors",'Basic L2'!$N$2:$N$27,"<>")+COUNTIFS('Advanced L1'!$B$2:$B$78,"Doors",'Advanced L1'!$N$2:$N$78,"<>")+COUNTIFS('Germany L1'!$B$2:$B$37,"Doors",'Germany L1'!$N$2:$N$37,"<>")+COUNTIFS('Japan L7'!$B$2:$B$112,"Doors",'Japan L7'!$N$2:$N$112,"<>")+COUNTIFS('Snowden Tower L1'!$B$2:$B$86,"Doors",'Snowden Tower L1'!$N$2:$N$86,"<>")+COUNTIFS('Snowden Tower L2'!$B$2:$B$70,"Doors",'Snowden Tower L2'!$N$2:$N$70,"<>"))=0,"N/A",(SUMIF('Basic L1'!$B$2:$B$20,"Doors",'Basic L1'!$N$2:$N$20)+SUMIF('Basic L2'!$B$2:$B$27,"Doors",'Basic L2'!$N$2:$N$27)+SUMIF('Advanced L1'!$B$2:$B$78,"Doors",'Advanced L1'!$N$2:$N$78)+SUMIF('Germany L1'!$B$2:$B$37,"Doors",'Germany L1'!$N$2:$N$37)+SUMIF('Japan L7'!$B$2:$B$112,"Doors",'Japan L7'!$N$2:$N$112)+SUMIF('Snowden Tower L1'!$B$2:$B$86,"Doors",'Snowden Tower L1'!$N$2:$N$86)+SUMIF('Snowden Tower L2'!$B$2:$B$70,"Doors",'Snowden Tower L2'!$N$2:$N$70))/(COUNTIFS('Basic L1'!$B$2:$B$20,"Doors",'Basic L1'!$N$2:$N$20,"<>")+COUNTIFS('Basic L2'!$B$2:$B$27,"Doors",'Basic L2'!$N$2:$N$27,"<>")+COUNTIFS('Advanced L1'!$B$2:$B$78,"Doors",'Advanced L1'!$N$2:$N$78,"<>")+COUNTIFS('Germany L1'!$B$2:$B$37,"Doors",'Germany L1'!$N$2:$N$37,"<>")+COUNTIFS('Japan L7'!$B$2:$B$112,"Doors",'Japan L7'!$N$2:$N$112,"<>")+COUNTIFS('Snowden Tower L1'!$B$2:$B$86,"Doors",'Snowden Tower L1'!$N$2:$N$86,"<>")+COUNTIFS('Snowden Tower L2'!$B$2:$B$70,"Doors",'Snowden Tower L2'!$N$2:$N$70,"<>"))) -> -6.4180442 | H6: =IF((COUNTIFS('Basic L1'!$B$2:$B$20,"Doors",'Basic L1'!$O$2:$O$20,"<>")+COUNTIFS('Basic L2'!$B$2:$B$27,"Doors",'Basic L2'!$O$2:$O$27,"<>")+COUNTIFS('Advanced L1'!$B$2:$B$78,"Doors",'Advanced L1'!$O$2:$O$78,"<>")+COUNTIFS('Germany L1'!$B$2:$B$37,"Doors",'Germany L1'!$O$2:$O$37,"<>")+COUNTIFS('Japan L7'!$B$2:$B$112,"Doors",'Japan L7'!$O$2:$O$112,"<>")+COUNTIFS('Snowden Tower L1'!$B$2:$B$86,"Doors",'Snowden Tower L1'!$O$2:$O$86,"<>")+COUNTIFS('Snowden Tower L2'!$B$2:$B$70,"Doors",'Snowden Tower L2'!$O$2:$O$70,"<>"))=0,"N/A",(SUMIF('Basic L1'!$B$2:$B$20,"Doors",'Basic L1'!$O$2:$O$20)+SUMIF('Basic L2'!$B$2:$B$27,"Doors",'Basic L2'!$O$2:$O$27)+SUMIF('Advanced L1'!$B$2:$B$78,"Doors",'Advanced L1'!$O$2:$O$78)+SUMIF('Germany L1'!$B$2:$B$37,"Doors",'Germany L1'!$O$2:$O$37)+SUMIF('Japan L7'!$B$2:$B$112,"Doors",'Japan L7'!$O$2:$O$112)+SUMIF('Snowden Tower L1'!$B$2:$B$86,"Doors",'Snowden Tower L1'!$O$2:$O$86)+SUMIF('Snowden Tower L2'!$B$2:$B$70,"Doors",'Snowden Tower L2'!$O$2:$O$70))/(COUNTIFS('Basic L1'!$B$2:$B$20,"Doors",'Basic L1'!$O$2:$O$20,"<>")+COUNTIFS('Basic L2'!$B$2:$B$27,"Doors",'Basic L2'!$O$2:$O$27,"<>")+COUNTIFS('Advanced L1'!$B$2:$B$78,"Doors",'Advanced L1'!$O$2:$O$78,"<>")+COUNTIFS('Germany L1'!$B$2:$B$37,"Doors",'Germany L1'!$O$2:$O$37,"<>")+COUNTIFS('Japan L7'!$B$2:$B$112,"Doors",'Japan L7'!$O$2:$O$112,"<>")+COUNTIFS('Snowden Tower L1'!$B$2:$B$86,"Doors",'Snowden Tower L1'!$O$2:$O$86,"<>")+COUNTIFS('Snowden Tower L2'!$B$2:$B$70,"Doors",'Snowden Tower L2'!$O$2:$O$70,"<>"))) -> 0.54762696 | I6: =IF((COUNTIFS('Basic L1'!$B$2:$B$20,"Doors",'Basic L1'!$S$2:$S$20,"<>")+COUNTIFS('Basic L2'!$B$2:$B$27,"Doors",'Basic L2'!$S$2:$S$27,"<>")+COUNTIFS('Advanced L1'!$B$2:$B$78,"Doors",'Advanced L1'!$S$2:$S$78,"<>")+COUNTIFS('Germany L1'!$B$2:$B$37,"Doors",'Germany L1'!$S$2:$S$37,"<>")+COUNTIFS('Japan L7'!$B$2:$B$112,"Doors",'Japan L7'!$S$2:$S$112,"<>")+COUNTIFS('Snowden Tower L1'!$B$2:$B$86,"Doors",'Snowden Tower L1'!$S$2:$S$86,"<>")+COUNTIFS('Snowden Tower L2'!$B$2:$B$70,"Doors",'Snowden Tower L2'!$S$2:$S$70,"<>"))=0,"N/A",(SUMIF('Basic L1'!$B$2:$B$20,"Doors",'Basic L1'!$S$2:$S$20)+SUMIF('Basic L2'!$B$2:$B$27,"Doors",'Basic L2'!$S$2:$S$27)+SUMIF('Advanced L1'!$B$2:$B$78,"Doors",'Advanced L1'!$S$2:$S$78)+SUMIF('Germany L1'!$B$2:$B$37,"Doors",'Germany L1'!$S$2:$S$37)+SUMIF('Japan L7'!$B$2:$B$112,"Doors",'Japan L7'!$S$2:$S$112)+SUMIF('Snowden Tower L1'!$B$2:$B$86,"Doors",'Snowden Tower L1'!$S$2:$S$86)+SUMIF('Snowden Tower L2'!$B$2:$B$70,"Doors",'Snowden Tower L2'!$S$2:$S$70))/(COUNTIFS('Basic L1'!$B$2:$B$20,"Doors",'Basic L1'!$S$2:$S$20,"<>")+COUNTIFS('Basic L2'!$B$2:$B$27,"Doors",'Basic L2'!$S$2:$S$27,"<>")+COUNTIFS('Advanced L1'!$B$2:$B$78,"Doors",'Advanced L1'!$S$2:$S$78,"<>")+COUNTIFS('Germany L1'!$B$2:$B$37,"Doors",'Germany L1'!$S$2:$S$37,"<>")+COUNTIFS('Japan L7'!$B$2:$B$112,"Doors",'Japan L7'!$S$2:$S$112,"<>")+COUNTIFS('Snowden Tower L1'!$B$2:$B$86,"Doors",'Snowden Tower L1'!$S$2:$S$86,"<>")+COUNTIFS('Snowden Tower L2'!$B$2:$B$70,"Doors",'Snowden Tower L2'!$S$2:$S$70,"<>"))) -> 7.8153976 | J6: =IF((COUNTIFS('Basic L1'!$B$2:$B$20,"Doors",'Basic L1'!$S$2:$S$20,"<>")+COUNTIFS('Basic L2'!$B$2:$B$27,"Doors",'Basic L2'!$S$2:$S$27,"<>")+COUNTIFS('Advanced L1'!$B$2:$B$78,"Doors",'Advanced L1'!$S$2:$S$78,"<>")+COUNTIFS('Germany L1'!$B$2:$B$37,"Doors",'Germany L1'!$S$2:$S$37,"<>")+COUNTIFS('Japan L7'!$B$2:$B$112,"Doors",'Japan L7'!$S$2:$S$112,"<>")+COUNTIFS('Snowden Tower L1'!$B$2:$B$86,"Doors",'Snowden Tower L1'!$S$2:$S$86,"<>")+COUNTIFS('Snowden Tower L2'!$B$2:$B$70,"Doors",'Snowden Tower L2'!$S$2:$S$70,"<>"))=0,"N/A",(COUNTIFS('Basic L1'!$B$2:$B$20,"Doors",'Basic L1'!$S$2:$S$20,">1")+COUNTIFS('Basic L2'!$B$2:$B$27,"Doors",'Basic L2'!$S$2:$S$27,">1")+COUNTIFS('Advanced L1'!$B$2:$B$78,"Doors",'Advanced L1'!$S$2:$S$78,">1")+COUNTIFS('Germany L1'!$B$2:$B$37,"Doors",'Germany L1'!$S$2:$S$37,">1")+COUNTIFS('Japan L7'!$B$2:$B$112,"Doors",'Japan L7'!$S$2:$S$112,">1")+COUNTIFS('Snowden Tower L1'!$B$2:$B$86,"Doors",'Snowden Tower L1'!$S$2:$S$86,">1")+COUNTIFS('Snowden Tower L2'!$B$2:$B$70,"Doors",'Snowden Tower L2'!$S$2:$S$70,">1"))/(COUNTIFS('Basic L1'!$B$2:$B$20,"Doors",'Basic L1'!$S$2:$S$20,"<>")+COUNTIFS('Basic L2'!$B$2:$B$27,"Doors",'Basic L2'!$S$2:$S$27,"<>")+COUNTIFS('Advanced L1'!$B$2:$B$78,"Doors",'Advanced L1'!$S$2:$S$78,"<>")+COUNTIFS('Germany L1'!$B$2:$B$37,"Doors",'Germany L1'!$S$2:$S$37,"<>")+COUNTIFS('Japan L7'!$B$2:$B$112,"Doors",'Japan L7'!$S$2:$S$112,"<>")+COUNTIFS('Snowden Tower L1'!$B$2:$B$86,"Doors",'Snowden Tower L1'!$S$2:$S$86,"<>")+COUNTIFS('Snowden Tower L2'!$B$2:$B$70,"Doors",'Snowden Tower L2'!$S$2:$S$70,"<>"))) -> 0.50862069 | K6: =COUNTIFS('Basic L1'!$B$2:$B$20,"Doors",'Basic L1'!$K$2:$K$20,">15")+COUNTIFS('Basic L2'!$B$2:$B$27,"Doors",'Basic L2'!$K$2:$K$27,">15")+COUNTIFS('Advanced L1'!$B$2:$B$78,"Doors",'Advanced L1'!$K$2:$K$78,">15")+COUNTIFS('Germany L1'!$B$2:$B$37,"Doors",'Germany L1'!$K$2:$K$37,">15")+COUNTIFS('Japan L7'!$B$2:$B$112,"Doors",'Japan L7'!$K$2:$K$112,">15")+COUNTIFS('Snowden Tower L1'!$B$2:$B$86,"Doors",'Snowden Tower L1'!$K$2:$K$86,">15")+COUNTIFS('Snowden Tower L2'!$B$2:$B$70,"Doors",'Snowden Tower L2'!$K$2:$K$70,">15") -> 14 | L6: 45.7293
A7: Window Tags | B7: =COUNTIF('Basic L1'!$B$2:$B$20,"Windows")+COUNTIF('Basic L2'!$B$2:$B$27,"Windows")+COUNTIF('Advanced L1'!$B$2:$B$78,"Windows")+COUNTIF('Germany L1'!$B$2:$B$37,"Windows")+COUNTIF('Japan L7'!$B$2:$B$112,"Windows")+COUNTIF('Snowden Tower L1'!$B$2:$B$86,"Windows")+COUNTIF('Snowden Tower L2'!$B$2:$B$70,"Windows") -> 45 | C7: =IF((COUNTIFS('Basic L1'!$B$2:$B$20,"Windows",'Basic L1'!$K$2:$K$20,"<>")+COUNTIFS('Basic L2'!$B$2:$B$27,"Windows",'Basic L2'!$K$2:$K$27,"<>")+COUNTIFS('Advanced L1'!$B$2:$B$78,"Windows",'Advanced L1'!$K$2:$K$78,"<>")+COUNTIFS('Germany L1'!$B$2:$B$37,"Windows",'Germany L1'!$K$2:$K$37,"<>")+COUNTIFS('Japan L7'!$B$2:$B$112,"Windows",'Japan L7'!$K$2:$K$112,"<>")+COUNTIFS('Snowden Tower L1'!$B$2:$B$86,"Windows",'Snowden Tower L1'!$K$2:$K$86,"<>")+COUNTIFS('Snowden Tower L2'!$B$2:$B$70,"Windows",'Snowden Tower L2'!$K$2:$K$70,"<>"))=0,"N/A",(SUMIF('Basic L1'!$B$2:$B$20,"Windows",'Basic L1'!$K$2:$K$20)+SUMIF('Basic L2'!$B$2:$B$27,"Windows",'Basic L2'!$K$2:$K$27)+SUMIF('Advanced L1'!$B$2:$B$78,"Windows",'Advanced L1'!$K$2:$K$78)+SUMIF('Germany L1'!$B$2:$B$37,"Windows",'Germany L1'!$K$2:$K$37)+SUMIF('Japan L7'!$B$2:$B$112,"Windows",'Japan L7'!$K$2:$K$112)+SUMIF('Snowden Tower L1'!$B$2:$B$86,"Windows",'Snowden Tower L1'!$K$2:$K$86)+SUMIF('Snowden Tower L2'!$B$2:$B$70,"Windows",'Snowden Tower L2'!$K$2:$K$70))/(COUNTIFS('Basic L1'!$B$2:$B$20,"Windows",'Basic L1'!$K$2:$K$20,"<>")+COUNTIFS('Basic L2'!$B$2:$B$27,"Windows",'Basic L2'!$K$2:$K$27,"<>")+COUNTIFS('Advanced L1'!$B$2:$B$78,"Windows",'Advanced L1'!$K$2:$K$78,"<>")+COUNTIFS('Germany L1'!$B$2:$B$37,"Windows",'Germany L1'!$K$2:$K$37,"<>")+COUNTIFS('Japan L7'!$B$2:$B$112,"Windows",'Japan L7'!$K$2:$K$112,"<>")+COUNTIFS('Snowden Tower L1'!$B$2:$B$86,"Windows",'Snowden Tower L1'!$K$2:$K$86,"<>")+COUNTIFS('Snowden Tower L2'!$B$2:$B$70,"Windows",'Snowden Tower L2'!$K$2:$K$70,"<>"))) -> 4.7687801 | D7: {=IFERROR(MEDIAN(IF('Basic L1'!$B$2:$B$20="Windows",'Basic L1'!$K$2:$K$20),IF('Basic L2'!$B$2:$B$27="Windows",'Basic L2'!$K$2:$K$27),IF('Advanced L1'!$B$2:$B$78="Windows",'Advanced L1'!$K$2:$K$78),IF('Germany L1'!$B$2:$B$37="Windows",'Germany L1'!$K$2:$K$37),IF('Japan L7'!$B$2:$B$112="Windows",'Japan L7'!$K$2:$K$112),IF('Snowden Tower L1'!$B$2:$B$86="Windows",'Snowden Tower L1'!$K$2:$K$86),IF('Snowden Tower L2'!$B$2:$B$70="Windows",'Snowden Tower L2'!$K$2:$K$70)),"N/A")} -> 0.2983 | E7: =IF((COUNTIFS('Basic L1'!$B$2:$B$20,"Windows",'Basic L1'!$K$2:$K$20,"<>")+COUNTIFS('Basic L2'!$B$2:$B$27,"Windows",'Basic L2'!$K$2:$K$27,"<>")+COUNTIFS('Advanced L1'!$B$2:$B$78,"Windows",'Advanced L1'!$K$2:$K$78,"<>")+COUNTIFS('Germany L1'!$B$2:$B$37,"Windows",'Germany L1'!$K$2:$K$37,"<>")+COUNTIFS('Japan L7'!$B$2:$B$112,"Windows",'Japan L7'!$K$2:$K$112,"<>")+COUNTIFS('Snowden Tower L1'!$B$2:$B$86,"Windows",'Snowden Tower L1'!$K$2:$K$86,"<>")+COUNTIFS('Snowden Tower L2'!$B$2:$B$70,"Windows",'Snowden Tower L2'!$K$2:$K$70,"<>"))=0,"N/A",SQRT((SUMPRODUCT(('Basic L1'!$B$2:$B$20="Windows")*('Basic L1'!$K$2:$K$20)*('Basic L1'!$K$2:$K$20))+SUMPRODUCT(('Basic L2'!$B$2:$B$27="Windows")*('Basic L2'!$K$2:$K$27)*('Basic L2'!$K$2:$K$27))+SUMPRODUCT(('Advanced L1'!$B$2:$B$78="Windows")*('Advanced L1'!$K$2:$K$78)*('Advanced L1'!$K$2:$K$78))+SUMPRODUCT(('Germany L1'!$B$2:$B$37="Windows")*('Germany L1'!$K$2:$K$37)*('Germany L1'!$K$2:$K$37))+SUMPRODUCT(('Japan L7'!$B$2:$B$112="Windows")*('Japan L7'!$K$2:$K$112)*('Japan L7'!$K$2:$K$112))+SUMPRODUCT(('Snowden Tower L1'!$B$2:$B$86="Windows")*('Snowden Tower L1'!$K$2:$K$86)*('Snowden Tower L1'!$K$2:$K$86))+SUMPRODUCT(('Snowden Tower L2'!$B$2:$B$70="Windows")*('Snowden Tower L2'!$K$2:$K$70)*('Snowden Tower L2'!$K$2:$K$70)))/(COUNTIFS('Basic L1'!$B$2:$B$20,"Windows",'Basic L1'!$K$2:$K$20,"<>")+COUNTIFS('Basic L2'!$B$2:$B$27,"Windows",'Basic L2'!$K$2:$K$27,"<>")+COUNTIFS('Advanced L1'!$B$2:$B$78,"Windows",'Advanced L1'!$K$2:$K$78,"<>")+COUNTIFS('Germany L1'!$B$2:$B$37,"Windows",'Germany L1'!$K$2:$K$37,"<>")+COUNTIFS('Japan L7'!$B$2:$B$112,"Windows",'Japan L7'!$K$2:$K$112,"<>")+COUNTIFS('Snowden Tower L1'!$B$2:$B$86,"Windows",'Snowden Tower L1'!$K$2:$K$86,"<>")+COUNTIFS('Snowden Tower L2'!$B$2:$B$70,"Windows",'Snowden Tower L2'!$K$2:$K$70,"<>")))) -> 17.63413 | F7: =IF((COUNTIFS('Basic L1'!$B$2:$B$20,"Windows",'Basic L1'!$R$2:$R$20,"<>")+COUNTIFS('Basic L2'!$B$2:$B$27,"Windows",'Basic L2'!$R$2:$R$27,"<>")+COUNTIFS('Advanced L1'!$B$2:$B$78,"Windows",'Advanced L1'!$R$2:$R$78,"<>")+COUNTIFS('Germany L1'!$B$2:$B$37,"Windows",'Germany L1'!$R$2:$R$37,"<>")+COUNTIFS('Japan L7'!$B$2:$B$112,"Windows",'Japan L7'!$R$2:$R$112,"<>")+COUNTIFS('Snowden Tower L1'!$B$2:$B$86,"Windows",'Snowden Tower L1'!$R$2:$R$86,"<>")+COUNTIFS('Snowden Tower L2'!$B$2:$B$70,"Windows",'Snowden Tower L2'!$R$2:$R$70,"<>"))=0,"N/A",(SUMIFS('Basic L1'!$R$2:$R$20,'Basic L1'!$B$2:$B$20,"Windows")+SUMIFS('Basic L2'!$R$2:$R$27,'Basic L2'!$B$2:$B$27,"Windows")+SUMIFS('Advanced L1'!$R$2:$R$78,'Advanced L1'!$B$2:$B$78,"Windows")+SUMIFS('Germany L1'!$R$2:$R$37,'Germany L1'!$B$2:$B$37,"Windows")+SUMIFS('Japan L7'!$R$2:$R$112,'Japan L7'!$B$2:$B$112,"Windows")+SUMIFS('Snowden Tower L1'!$R$2:$R$86,'Snowden Tower L1'!$B$2:$B$86,"Windows")+SUMIFS('Snowden Tower L2'!$R$2:$R$70,'Snowden Tower L2'!$B$2:$B$70,"Windows"))/(COUNTIFS('Basic L1'!$B$2:$B$20,"Windows",'Basic L1'!$R$2:$R$20,"<>")+COUNTIFS('Basic L2'!$B$2:$B$27,"Windows",'Basic L2'!$R$2:$R$27,"<>")+COUNTIFS('Advanced L1'!$B$2:$B$78,"Windows",'Advanced L1'!$R$2:$R$78,"<>")+COUNTIFS('Germany L1'!$B$2:$B$37,"Windows",'Germany L1'!$R$2:$R$37,"<>")+COUNTIFS('Japan L7'!$B$2:$B$112,"Windows",'Japan L7'!$R$2:$R$112,"<>")+COUNTIFS('Snowden Tower L1'!$B$2:$B$86,"Windows",'Snowden Tower L1'!$R$2:$R$86,"<>")+COUNTIFS('Snowden Tower L2'!$B$2:$B$70,"Windows",'Snowden Tower L2'!$R$2:$R$70,"<>"))) -> 0.86666667 | G7: =IF((COUNTIFS('Basic L1'!$B$2:$B$20,"Windows",'Basic L1'!$N$2:$N$20,"<>")+COUNTIFS('Basic L2'!$B$2:$B$27,"Windows",'Basic L2'!$N$2:$N$27,"<>")+COUNTIFS('Advanced L1'!$B$2:$B$78,"Windows",'Advanced L1'!$N$2:$N$78,"<>")+COUNTIFS('Germany L1'!$B$2:$B$37,"Windows",'Germany L1'!$N$2:$N$37,"<>")+COUNTIFS('Japan L7'!$B$2:$B$112,"Windows",'Japan L7'!$N$2:$N$112,"<>")+COUNTIFS('Snowden Tower L1'!$B$2:$B$86,"Windows",'Snowden Tower L1'!$N$2:$N$86,"<>")+COUNTIFS('Snowden Tower L2'!$B$2:$B$70,"Windows",'Snowden Tower L2'!$N$2:$N$70,"<>"))=0,"N/A",(SUMIF('Basic L1'!$B$2:$B$20,"Windows",'Basic L1'!$N$2:$N$20)+SUMIF('Basic L2'!$B$2:$B$27,"Windows",'Basic L2'!$N$2:$N$27)+SUMIF('Advanced L1'!$B$2:$B$78,"Windows",'Advanced L1'!$N$2:$N$78)+SUMIF('Germany L1'!$B$2:$B$37,"Windows",'Germany L1'!$N$2:$N$37)+SUMIF('Japan L7'!$B$2:$B$112,"Windows",'Japan L7'!$N$2:$N$112)+SUMIF('Snowden Tower L1'!$B$2:$B$86,"Windows",'Snowden Tower L1'!$N$2:$N$86)+SUMIF('Snowden Tower L2'!$B$2:$B$70,"Windows",'Snowden Tower L2'!$N$2:$N$70))/(COUNTIFS('Basic L1'!$B$2:$B$20,"Windows",'Basic L1'!$N$2:$N$20,"<>")+COUNTIFS('Basic L2'!$B$2:$B$27,"Windows",'Basic L2'!$N$2:$N$27,"<>")+COUNTIFS('Advanced L1'!$B$2:$B$78,"Windows",'Advanced L1'!$N$2:$N$78,"<>")+COUNTIFS('Germany L1'!$B$2:$B$37,"Windows",'Germany L1'!$N$2:$N$37,"<>")+COUNTIFS('Japan L7'!$B$2:$B$112,"Windows",'Japan L7'!$N$2:$N$112,"<>")+COUNTIFS('Snowden Tower L1'!$B$2:$B$86,"Windows",'Snowden Tower L1'!$N$2:$N$86,"<>")+COUNTIFS('Snowden Tower L2'!$B$2:$B$70,"Windows",'Snowden Tower L2'!$N$2:$N$70,"<>"))) -> -2.9143909 | H7: =IF((COUNTIFS('Basic L1'!$B$2:$B$20,"Windows",'Basic L1'!$O$2:$O$20,"<>")+COUNTIFS('Basic L2'!$B$2:$B$27,"Windows",'Basic L2'!$O$2:$O$27,"<>")+COUNTIFS('Advanced L1'!$B$2:$B$78,"Windows",'Advanced L1'!$O$2:$O$78,"<>")+COUNTIFS('Germany L1'!$B$2:$B$37,"Windows",'Germany L1'!$O$2:$O$37,"<>")+COUNTIFS('Japan L7'!$B$2:$B$112,"Windows",'Japan L7'!$O$2:$O$112,"<>")+COUNTIFS('Snowden Tower L1'!$B$2:$B$86,"Windows",'Snowden Tower L1'!$O$2:$O$86,"<>")+COUNTIFS('Snowden Tower L2'!$B$2:$B$70,"Windows",'Snowden Tower L2'!$O$2:$O$70,"<>"))=0,"N/A",(SUMIF('Basic L1'!$B$2:$B$20,"Windows",'Basic L1'!$O$2:$O$20)+SUMIF('Basic L2'!$B$2:$B$27,"Windows",'Basic L2'!$O$2:$O$27)+SUMIF('Advanced L1'!$B$2:$B$78,"Windows",'Advanced L1'!$O$2:$O$78)+SUMIF('Germany L1'!$B$2:$B$37,"Windows",'Germany L1'!$O$2:$O$37)+SUMIF('Japan L7'!$B$2:$B$112,"Windows",'Japan L7'!$O$2:$O$112)+SUMIF('Snowden Tower L1'!$B$2:$B$86,"Windows",'Snowden Tower L1'!$O$2:$O$86)+SUMIF('Snowden Tower L2'!$B$2:$B$70,"Windows",'Snowden Tower L2'!$O$2:$O$70))/(COUNTIFS('Basic L1'!$B$2:$B$20,"Windows",'Basic L1'!$O$2:$O$20,"<>")+COUNTIFS('Basic L2'!$B$2:$B$27,"Windows",'Basic L2'!$O$2:$O$27,"<>")+COUNTIFS('Advanced L1'!$B$2:$B$78,"Windows",'Advanced L1'!$O$2:$O$78,"<>")+COUNTIFS('Germany L1'!$B$2:$B$37,"Windows",'Germany L1'!$O$2:$O$37,"<>")+COUNTIFS('Japan L7'!$B$2:$B$112,"Windows",'Japan L7'!$O$2:$O$112,"<>")+COUNTIFS('Snowden Tower L1'!$B$2:$B$86,"Windows",'Snowden Tower L1'!$O$2:$O$86,"<>")+COUNTIFS('Snowden Tower L2'!$B$2:$B$70,"Windows",'Snowden Tower L2'!$O$2:$O$70,"<>"))) -> 0.85727871 | I7: =IF((COUNTIFS('Basic L1'!$B$2:$B$20,"Windows",'Basic L1'!$S$2:$S$20,"<>")+COUNTIFS('Basic L2'!$B$2:$B$27,"Windows",'Basic L2'!$S$2:$S$27,"<>")+COUNTIFS('Advanced L1'!$B$2:$B$78,"Windows",'Advanced L1'!$S$2:$S$78,"<>")+COUNTIFS('Germany L1'!$B$2:$B$37,"Windows",'Germany L1'!$S$2:$S$37,"<>")+COUNTIFS('Japan L7'!$B$2:$B$112,"Windows",'Japan L7'!$S$2:$S$112,"<>")+COUNTIFS('Snowden Tower L1'!$B$2:$B$86,"Windows",'Snowden Tower L1'!$S$2:$S$86,"<>")+COUNTIFS('Snowden Tower L2'!$B$2:$B$70,"Windows",'Snowden Tower L2'!$S$2:$S$70,"<>"))=0,"N/A",(SUMIF('Basic L1'!$B$2:$B$20,"Windows",'Basic L1'!$S$2:$S$20)+SUMIF('Basic L2'!$B$2:$B$27,"Windows",'Basic L2'!$S$2:$S$27)+SUMIF('Advanced L1'!$B$2:$B$78,"Windows",'Advanced L1'!$S$2:$S$78)+SUMIF('Germany L1'!$B$2:$B$37,"Windows",'Germany L1'!$S$2:$S$37)+SUMIF('Japan L7'!$B$2:$B$112,"Windows",'Japan L7'!$S$2:$S$112)+SUMIF('Snowden Tower L1'!$B$2:$B$86,"Windows",'Snowden Tower L1'!$S$2:$S$86)+SUMIF('Snowden Tower L2'!$B$2:$B$70,"Windows",'Snowden Tower L2'!$S$2:$S$70))/(COUNTIFS('Basic L1'!$B$2:$B$20,"Windows",'Basic L1'!$S$2:$S$20,"<>")+COUNTIFS('Basic L2'!$B$2:$B$27,"Windows",'Basic L2'!$S$2:$S$27,"<>")+COUNTIFS('Advanced L1'!$B$2:$B$78,"Windows",'Advanced L1'!$S$2:$S$78,"<>")+COUNTIFS('Germany L1'!$B$2:$B$37,"Windows",'Germany L1'!$S$2:$S$37,"<>")+COUNTIFS('Japan L7'!$B$2:$B$112,"Windows",'Japan L7'!$S$2:$S$112,"<>")+COUNTIFS('Snowden Tower L1'!$B$2:$B$86,"Windows",'Snowden Tower L1'!$S$2:$S$86,"<>")+COUNTIFS('Snowden Tower L2'!$B$2:$B$70,"Windows",'Snowden Tower L2'!$S$2:$S$70,"<>"))) -> 4.429917 | J7: =IF((COUNTIFS('Basic L1'!$B$2:$B$20,"Windows",'Basic L1'!$S$2:$S$20,"<>")+COUNTIFS('Basic L2'!$B$2:$B$27,"Windows",'Basic L2'!$S$2:$S$27,"<>")+COUNTIFS('Advanced L1'!$B$2:$B$78,"Windows",'Advanced L1'!$S$2:$S$78,"<>")+COUNTIFS('Germany L1'!$B$2:$B$37,"Windows",'Germany L1'!$S$2:$S$37,"<>")+COUNTIFS('Japan L7'!$B$2:$B$112,"Windows",'Japan L7'!$S$2:$S$112,"<>")+COUNTIFS('Snowden Tower L1'!$B$2:$B$86,"Windows",'Snowden Tower L1'!$S$2:$S$86,"<>")+COUNTIFS('Snowden Tower L2'!$B$2:$B$70,"Windows",'Snowden Tower L2'!$S$2:$S$70,"<>"))=0,"N/A",(COUNTIFS('Basic L1'!$B$2:$B$20,"Windows",'Basic L1'!$S$2:$S$20,">1")+COUNTIFS('Basic L2'!$B$2:$B$27,"Windows",'Basic L2'!$S$2:$S$27,">1")+COUNTIFS('Advanced L1'!$B$2:$B$78,"Windows",'Advanced L1'!$S$2:$S$78,">1")+COUNTIFS('Germany L1'!$B$2:$B$37,"Windows",'Germany L1'!$S$2:$S$37,">1")+COUNTIFS('Japan L7'!$B$2:$B$112,"Windows",'Japan L7'!$S$2:$S$112,">1")+COUNTIFS('Snowden Tower L1'!$B$2:$B$86,"Windows",'Snowden Tower L1'!$S$2:$S$86,">1")+COUNTIFS('Snowden Tower L2'!$B$2:$B$70,"Windows",'Snowden Tower L2'!$S$2:$S$70,">1"))/(COUNTIFS('Basic L1'!$B$2:$B$20,"Windows",'Basic L1'!$S$2:$S$20,"<>")+COUNTIFS('Basic L2'!$B$2:$B$27,"Windows",'Basic L2'!$S$2:$S$27,"<>")+COUNTIFS('Advanced L1'!$B$2:$B$78,"Windows",'Advanced L1'!$S$2:$S$78,"<>")+COUNTIFS('Germany L1'!$B$2:$B$37,"Windows",'Germany L1'!$S$2:$S$37,"<>")+COUNTIFS('Japan L7'!$B$2:$B$112,"Windows",'Japan L7'!$S$2:$S$112,"<>")+COUNTIFS('Snowden Tower L1'!$B$2:$B$86,"Windows",'Snowden Tower L1'!$S$2:$S$86,"<>")+COUNTIFS('Snowden Tower L2'!$B$2:$B$70,"Windows",'Snowden Tower L2'!$S$2:$S$70,"<>"))) -> 0.31111111 | K7: =COUNTIFS('Basic L1'!$B$2:$B$20,"Windows",'Basic L1'!$K$2:$K$20,">15")+COUNTIFS('Basic L2'!$B$2:$B$27,"Windows",'Basic L2'!$K$2:$K$27,">15")+COUNTIFS('Advanced L1'!$B$2:$B$78,"Windows",'Advanced L1'!$K$2:$K$78,">15")+COUNTIFS('Germany L1'!$B$2:$B$37,"Windows",'Germany L1'!$K$2:$K$37,">15")+COUNTIFS('Japan L7'!$B$2:$B$112,"Windows",'Japan L7'!$K$2:$K$112,">15")+COUNTIFS('Snowden Tower L1'!$B$2:$B$86,"Windows",'Snowden Tower L1'!$K$2:$K$86,">15")+COUNTIFS('Snowden Tower L2'!$B$2:$B$70,"Windows",'Snowden Tower L2'!$K$2:$K$70,">15") -> 3 | L7: 19.9535
A8: Wall Tags | B8: =COUNTIF('Basic L1'!$B$2:$B$20,"Walls")+COUNTIF('Basic L2'!$B$2:$B$27,"Walls")+COUNTIF('Advanced L1'!$B$2:$B$78,"Walls")+COUNTIF('Germany L1'!$B$2:$B$37,"Walls")+COUNTIF('Japan L7'!$B$2:$B$112,"Walls")+COUNTIF('Snowden Tower L1'!$B$2:$B$86,"Walls")+COUNTIF('Snowden Tower L2'!$B$2:$B$70,"Walls") -> 167 | C8: =IF((COUNTIFS('Basic L1'!$B$2:$B$20,"Walls",'Basic L1'!$K$2:$K$20,"<>")+COUNTIFS('Basic L2'!$B$2:$B$27,"Walls",'Basic L2'!$K$2:$K$27,"<>")+COUNTIFS('Advanced L1'!$B$2:$B$78,"Walls",'Advanced L1'!$K$2:$K$78,"<>")+COUNTIFS('Germany L1'!$B$2:$B$37,"Walls",'Germany L1'!$K$2:$K$37,"<>")+COUNTIFS('Japan L7'!$B$2:$B$112,"Walls",'Japan L7'!$K$2:$K$112,"<>")+COUNTIFS('Snowden Tower L1'!$B$2:$B$86,"Walls",'Snowden Tower L1'!$K$2:$K$86,"<>")+COUNTIFS('Snowden Tower L2'!$B$2:$B$70,"Walls",'Snowden Tower L2'!$K$2:$K$70,"<>"))=0,"N/A",(SUMIF('Basic L1'!$B$2:$B$20,"Walls",'Basic L1'!$K$2:$K$20)+SUMIF('Basic L2'!$B$2:$B$27,"Walls",'Basic L2'!$K$2:$K$27)+SUMIF('Advanced L1'!$B$2:$B$78,"Walls",'Advanced L1'!$K$2:$K$78)+SUMIF('Germany L1'!$B$2:$B$37,"Walls",'Germany L1'!$K$2:$K$37)+SUMIF('Japan L7'!$B$2:$B$112,"Walls",'Japan L7'!$K$2:$K$112)+SUMIF('Snowden Tower L1'!$B$2:$B$86,"Walls",'Snowden Tower L1'!$K$2:$K$86)+SUMIF('Snowden Tower L2'!$B$2:$B$70,"Walls",'Snowden Tower L2'!$K$2:$K$70))/(COUNTIFS('Basic L1'!$B$2:$B$20,"Walls",'Basic L1'!$K$2:$K$20,"<>")+COUNTIFS('Basic L2'!$B$2:$B$27,"Walls",'Basic L2'!$K$2:$K$27,"<>")+COUNTIFS('Advanced L1'!$B$2:$B$78,"Walls",'Advanced L1'!$K$2:$K$78,"<>")+COUNTIFS('Germany L1'!$B$2:$B$37,"Walls",'Germany L1'!$K$2:$K$37,"<>")+COUNTIFS('Japan L7'!$B$2:$B$112,"Walls",'Japan L7'!$K$2:$K$112,"<>")+COUNTIFS('Snowden Tower L1'!$B$2:$B$86,"Walls",'Snowden Tower L1'!$K$2:$K$86,"<>")+COUNTIFS('Snowden Tower L2'!$B$2:$B$70,"Walls",'Snowden Tower L2'!$K$2:$K$70,"<>"))) -> 2.2265433 | D8: {=IFERROR(MEDIAN(IF('Basic L1'!$B$2:$B$20="Walls",'Basic L1'!$K$2:$K$20),IF('Basic L2'!$B$2:$B$27="Walls",'Basic L2'!$K$2:$K$27),IF('Advanced L1'!$B$2:$B$78="Walls",'Advanced L1'!$K$2:$K$78),IF('Germany L1'!$B$2:$B$37="Walls",'Germany L1'!$K$2:$K$37),IF('Japan L7'!$B$2:$B$112="Walls",'Japan L7'!$K$2:$K$112),IF('Snowden Tower L1'!$B$2:$B$86="Walls",'Snowden Tower L1'!$K$2:$K$86),IF('Snowden Tower L2'!$B$2:$B$70="Walls",'Snowden Tower L2'!$K$2:$K$70)),"N/A")} -> 1.6480413 | E8: =IF((COUNTIFS('Basic L1'!$B$2:$B$20,"Walls",'Basic L1'!$K$2:$K$20,"<>")+COUNTIFS('Basic L2'!$B$2:$B$27,"Walls",'Basic L2'!$K$2:$K$27,"<>")+COUNTIFS('Advanced L1'!$B$2:$B$78,"Walls",'Advanced L1'!$K$2:$K$78,"<>")+COUNTIFS('Germany L1'!$B$2:$B$37,"Walls",'Germany L1'!$K$2:$K$37,"<>")+COUNTIFS('Japan L7'!$B$2:$B$112,"Walls",'Japan L7'!$K$2:$K$112,"<>")+COUNTIFS('Snowden Tower L1'!$B$2:$B$86,"Walls",'Snowden Tower L1'!$K$2:$K$86,"<>")+COUNTIFS('Snowden Tower L2'!$B$2:$B$70,"Walls",'Snowden Tower L2'!$K$2:$K$70,"<>"))=0,"N/A",SQRT((SUMPRODUCT(('Basic L1'!$B$2:$B$20="Walls")*('Basic L1'!$K$2:$K$20)*('Basic L1'!$K$2:$K$20))+SUMPRODUCT(('Basic L2'!$B$2:$B$27="Walls")*('Basic L2'!$K$2:$K$27)*('Basic L2'!$K$2:$K$27))+SUMPRODUCT(('Advanced L1'!$B$2:$B$78="Walls")*('Advanced L1'!$K$2:$K$78)*('Advanced L1'!$K$2:$K$78))+SUMPRODUCT(('Germany L1'!$B$2:$B$37="Walls")*('Germany L1'!$K$2:$K$37)*('Germany L1'!$K$2:$K$37))+SUMPRODUCT(('Japan L7'!$B$2:$B$112="Walls")*('Japan L7'!$K$2:$K$112)*('Japan L7'!$K$2:$K$112))+SUMPRODUCT(('Snowden Tower L1'!$B$2:$B$86="Walls")*('Snowden Tower L1'!$K$2:$K$86)*('Snowden Tower L1'!$K$2:$K$86))+SUMPRODUCT(('Snowden Tower L2'!$B$2:$B$70="Walls")*('Snowden Tower L2'!$K$2:$K$70)*('Snowden Tower L2'!$K$2:$K$70)))/(COUNTIFS('Basic L1'!$B$2:$B$20,"Walls",'Basic L1'!$K$2:$K$20,"<>")+COUNTIFS('Basic L2'!$B$2:$B$27,"Walls",'Basic L2'!$K$2:$K$27,"<>")+COUNTIFS('Advanced L1'!$B$2:$B$78,"Walls",'Advanced L1'!$K$2:$K$78,"<>")+COUNTIFS('Germany L1'!$B$2:$B$37,"Walls",'Germany L1'!$K$2:$K$37,"<>")+COUNTIFS('Japan L7'!$B$2:$B$112,"Walls",'Japan L7'!$K$2:$K$112,"<>")+COUNTIFS('Snowden Tower L1'!$B$2:$B$86,"Walls",'Snowden Tower L1'!$K$2:$K$86,"<>")+COUNTIFS('Snowden Tower L2'!$B$2:$B$70,"Walls",'Snowden Tower L2'!$K$2:$K$70,"<>")))) -> 3.0503649 | F8: =IF((COUNTIFS('Basic L1'!$B$2:$B$20,"Walls",'Basic L1'!$R$2:$R$20,"<>")+COUNTIFS('Basic L2'!$B$2:$B$27,"Walls",'Basic L2'!$R$2:$R$27,"<>")+COUNTIFS('Advanced L1'!$B$2:$B$78,"Walls",'Advanced L1'!$R$2:$R$78,"<>")+COUNTIFS('Germany L1'!$B$2:$B$37,"Walls",'Germany L1'!$R$2:$R$37,"<>")+COUNTIFS('Japan L7'!$B$2:$B$112,"Walls",'Japan L7'!$R$2:$R$112,"<>")+COUNTIFS('Snowden Tower L1'!$B$2:$B$86,"Walls",'Snowden Tower L1'!$R$2:$R$86,"<>")+COUNTIFS('Snowden Tower L2'!$B$2:$B$70,"Walls",'Snowden Tower L2'!$R$2:$R$70,"<>"))=0,"N/A",(SUMIFS('Basic L1'!$R$2:$R$20,'Basic L1'!$B$2:$B$20,"Walls")+SUMIFS('Basic L2'!$R$2:$R$27,'Basic L2'!$B$2:$B$27,"Walls")+SUMIFS('Advanced L1'!$R$2:$R$78,'Advanced L1'!$B$2:$B$78,"Walls")+SUMIFS('Germany L1'!$R$2:$R$37,'Germany L1'!$B$2:$B$37,"Walls")+SUMIFS('Japan L7'!$R$2:$R$112,'Japan L7'!$B$2:$B$112,"Walls")+SUMIFS('Snowden Tower L1'!$R$2:$R$86,'Snowden Tower L1'!$B$2:$B$86,"Walls")+SUMIFS('Snowden Tower L2'!$R$2:$R$70,'Snowden Tower L2'!$B$2:$B$70,"Walls"))/(COUNTIFS('Basic L1'!$B$2:$B$20,"Walls",'Basic L1'!$R$2:$R$20,"<>")+COUNTIFS('Basic L2'!$B$2:$B$27,"Walls",'Basic L2'!$R$2:$R$27,"<>")+COUNTIFS('Advanced L1'!$B$2:$B$78,"Walls",'Advanced L1'!$R$2:$R$78,"<>")+COUNTIFS('Germany L1'!$B$2:$B$37,"Walls",'Germany L1'!$R$2:$R$37,"<>")+COUNTIFS('Japan L7'!$B$2:$B$112,"Walls",'Japan L7'!$R$2:$R$112,"<>")+COUNTIFS('Snowden Tower L1'!$B$2:$B$86,"Walls",'Snowden Tower L1'!$R$2:$R$86,"<>")+COUNTIFS('Snowden Tower L2'!$B$2:$B$70,"Walls",'Snowden Tower L2'!$R$2:$R$70,"<>"))) -> 0.62874251 | G8: =IF((COUNTIFS('Basic L1'!$B$2:$B$20,"Walls",'Basic L1'!$N$2:$N$20,"<>")+COUNTIFS('Basic L2'!$B$2:$B$27,"Walls",'Basic L2'!$N$2:$N$27,"<>")+COUNTIFS('Advanced L1'!$B$2:$B$78,"Walls",'Advanced L1'!$N$2:$N$78,"<>")+COUNTIFS('Germany L1'!$B$2:$B$37,"Walls",'Germany L1'!$N$2:$N$37,"<>")+COUNTIFS('Japan L7'!$B$2:$B$112,"Walls",'Japan L7'!$N$2:$N$112,"<>")+COUNTIFS('Snowden Tower L1'!$B$2:$B$86,"Walls",'Snowden Tower L1'!$N$2:$N$86,"<>")+COUNTIFS('Snowden Tower L2'!$B$2:$B$70,"Walls",'Snowden Tower L2'!$N$2:$N$70,"<>"))=0,"N/A",(SUMIF('Basic L1'!$B$2:$B$20,"Walls",'Basic L1'!$N$2:$N$20)+SUMIF('Basic L2'!$B$2:$B$27,"Walls",'Basic L2'!$N$2:$N$27)+SUMIF('Advanced L1'!$B$2:$B$78,"Walls",'Advanced L1'!$N$2:$N$78)+SUMIF('Germany L1'!$B$2:$B$37,"Walls",'Germany L1'!$N$2:$N$37)+SUMIF('Japan L7'!$B$2:$B$112,"Walls",'Japan L7'!$N$2:$N$112)+SUMIF('Snowden Tower L1'!$B$2:$B$86,"Walls",'Snowden Tower L1'!$N$2:$N$86)+SUMIF('Snowden Tower L2'!$B$2:$B$70,"Walls",'Snowden Tower L2'!$N$2:$N$70))/(COUNTIFS('Basic L1'!$B$2:$B$20,"Walls",'Basic L1'!$N$2:$N$20,"<>")+COUNTIFS('Basic L2'!$B$2:$B$27,"Walls",'Basic L2'!$N$2:$N$27,"<>")+COUNTIFS('Advanced L1'!$B$2:$B$78,"Walls",'Advanced L1'!$N$2:$N$78,"<>")+COUNTIFS('Germany L1'!$B$2:$B$37,"Walls",'Germany L1'!$N$2:$N$37,"<>")+COUNTIFS('Japan L7'!$B$2:$B$112,"Walls",'Japan L7'!$N$2:$N$112,"<>")+COUNTIFS('Snowden Tower L1'!$B$2:$B$86,"Walls",'Snowden Tower L1'!$N$2:$N$86,"<>")+COUNTIFS('Snowden Tower L2'!$B$2:$B$70,"Walls",'Snowden Tower L2'!$N$2:$N$70,"<>"))) -> -0.068260146 | H8: =IF((COUNTIFS('Basic L1'!$B$2:$B$20,"Walls",'Basic L1'!$O$2:$O$20,"<>")+COUNTIFS('Basic L2'!$B$2:$B$27,"Walls",'Basic L2'!$O$2:$O$27,"<>")+COUNTIFS('Advanced L1'!$B$2:$B$78,"Walls",'Advanced L1'!$O$2:$O$78,"<>")+COUNTIFS('Germany L1'!$B$2:$B$37,"Walls",'Germany L1'!$O$2:$O$37,"<>")+COUNTIFS('Japan L7'!$B$2:$B$112,"Walls",'Japan L7'!$O$2:$O$112,"<>")+COUNTIFS('Snowden Tower L1'!$B$2:$B$86,"Walls",'Snowden Tower L1'!$O$2:$O$86,"<>")+COUNTIFS('Snowden Tower L2'!$B$2:$B$70,"Walls",'Snowden Tower L2'!$O$2:$O$70,"<>"))=0,"N/A",(SUMIF('Basic L1'!$B$2:$B$20,"Walls",'Basic L1'!$O$2:$O$20)+SUMIF('Basic L2'!$B$2:$B$27,"Walls",'Basic L2'!$O$2:$O$27)+SUMIF('Advanced L1'!$B$2:$B$78,"Walls",'Advanced L1'!$O$2:$O$78)+SUMIF('Germany L1'!$B$2:$B$37,"Walls",'Germany L1'!$O$2:$O$37)+SUMIF('Japan L7'!$B$2:$B$112,"Walls",'Japan L7'!$O$2:$O$112)+SUMIF('Snowden Tower L1'!$B$2:$B$86,"Walls",'Snowden Tower L1'!$O$2:$O$86)+SUMIF('Snowden Tower L2'!$B$2:$B$70,"Walls",'Snowden Tower L2'!$O$2:$O$70))/(COUNTIFS('Basic L1'!$B$2:$B$20,"Walls",'Basic L1'!$O$2:$O$20,"<>")+COUNTIFS('Basic L2'!$B$2:$B$27,"Walls",'Basic L2'!$O$2:$O$27,"<>")+COUNTIFS('Advanced L1'!$B$2:$B$78,"Walls",'Advanced L1'!$O$2:$O$78,"<>")+COUNTIFS('Germany L1'!$B$2:$B$37,"Walls",'Germany L1'!$O$2:$O$37,"<>")+COUNTIFS('Japan L7'!$B$2:$B$112,"Walls",'Japan L7'!$O$2:$O$112,"<>")+COUNTIFS('Snowden Tower L1'!$B$2:$B$86,"Walls",'Snowden Tower L1'!$O$2:$O$86,"<>")+COUNTIFS('Snowden Tower L2'!$B$2:$B$70,"Walls",'Snowden Tower L2'!$O$2:$O$70,"<>"))) -> 0.5099974 | I8: =IF((COUNTIFS('Basic L1'!$B$2:$B$20,"Walls",'Basic L1'!$S$2:$S$20,"<>")+COUNTIFS('Basic L2'!$B$2:$B$27,"Walls",'Basic L2'!$S$2:$S$27,"<>")+COUNTIFS('Advanced L1'!$B$2:$B$78,"Walls",'Advanced L1'!$S$2:$S$78,"<>")+COUNTIFS('Germany L1'!$B$2:$B$37,"Walls",'Germany L1'!$S$2:$S$37,"<>")+COUNTIFS('Japan L7'!$B$2:$B$112,"Walls",'Japan L7'!$S$2:$S$112,"<>")+COUNTIFS('Snowden Tower L1'!$B$2:$B$86,"Walls",'Snowden Tower L1'!$S$2:$S$86,"<>")+COUNTIFS('Snowden Tower L2'!$B$2:$B$70,"Walls",'Snowden Tower L2'!$S$2:$S$70,"<>"))=0,"N/A",(SUMIF('Basic L1'!$B$2:$B$20,"Walls",'Basic L1'!$S$2:$S$20)+SUMIF('Basic L2'!$B$2:$B$27,"Walls",'Basic L2'!$S$2:$S$27)+SUMIF('Advanced L1'!$B$2:$B$78,"Walls",'Advanced L1'!$S$2:$S$78)+SUMIF('Germany L1'!$B$2:$B$37,"Walls",'Germany L1'!$S$2:$S$37)+SUMIF('Japan L7'!$B$2:$B$112,"Walls",'Japan L7'!$S$2:$S$112)+SUMIF('Snowden Tower L1'!$B$2:$B$86,"Walls",'Snowden Tower L1'!$S$2:$S$86)+SUMIF('Snowden Tower L2'!$B$2:$B$70,"Walls",'Snowden Tower L2'!$S$2:$S$70))/(COUNTIFS('Basic L1'!$B$2:$B$20,"Walls",'Basic L1'!$S$2:$S$20,"<>")+COUNTIFS('Basic L2'!$B$2:$B$27,"Walls",'Basic L2'!$S$2:$S$27,"<>")+COUNTIFS('Advanced L1'!$B$2:$B$78,"Walls",'Advanced L1'!$S$2:$S$78,"<>")+COUNTIFS('Germany L1'!$B$2:$B$37,"Walls",'Germany L1'!$S$2:$S$37,"<>")+COUNTIFS('Japan L7'!$B$2:$B$112,"Walls",'Japan L7'!$S$2:$S$112,"<>")+COUNTIFS('Snowden Tower L1'!$B$2:$B$86,"Walls",'Snowden Tower L1'!$S$2:$S$86,"<>")+COUNTIFS('Snowden Tower L2'!$B$2:$B$70,"Walls",'Snowden Tower L2'!$S$2:$S$70,"<>"))) -> 1.3196133 | J8: =IF((COUNTIFS('Basic L1'!$B$2:$B$20,"Walls",'Basic L1'!$S$2:$S$20,"<>")+COUNTIFS('Basic L2'!$B$2:$B$27,"Walls",'Basic L2'!$S$2:$S$27,"<>")+COUNTIFS('Advanced L1'!$B$2:$B$78,"Walls",'Advanced L1'!$S$2:$S$78,"<>")+COUNTIFS('Germany L1'!$B$2:$B$37,"Walls",'Germany L1'!$S$2:$S$37,"<>")+COUNTIFS('Japan L7'!$B$2:$B$112,"Walls",'Japan L7'!$S$2:$S$112,"<>")+COUNTIFS('Snowden Tower L1'!$B$2:$B$86,"Walls",'Snowden Tower L1'!$S$2:$S$86,"<>")+COUNTIFS('Snowden Tower L2'!$B$2:$B$70,"Walls",'Snowden Tower L2'!$S$2:$S$70,"<>"))=0,"N/A",(COUNTIFS('Basic L1'!$B$2:$B$20,"Walls",'Basic L1'!$S$2:$S$20,">1")+COUNTIFS('Basic L2'!$B$2:$B$27,"Walls",'Basic L2'!$S$2:$S$27,">1")+COUNTIFS('Advanced L1'!$B$2:$B$78,"Walls",'Advanced L1'!$S$2:$S$78,">1")+COUNTIFS('Germany L1'!$B$2:$B$37,"Walls",'Germany L1'!$S$2:$S$37,">1")+COUNTIFS('Japan L7'!$B$2:$B$112,"Walls",'Japan L7'!$S$2:$S$112,">1")+COUNTIFS('Snowden Tower L1'!$B$2:$B$86,"Walls",'Snowden Tower L1'!$S$2:$S$86,">1")+COUNTIFS('Snowden Tower L2'!$B$2:$B$70,"Walls",'Snowden Tower L2'!$S$2:$S$70,">1"))/(COUNTIFS('Basic L1'!$B$2:$B$20,"Walls",'Basic L1'!$S$2:$S$20,"<>")+COUNTIFS('Basic L2'!$B$2:$B$27,"Walls",'Basic L2'!$S$2:$S$27,"<>")+COUNTIFS('Advanced L1'!$B$2:$B$78,"Walls",'Advanced L1'!$S$2:$S$78,"<>")+COUNTIFS('Germany L1'!$B$2:$B$37,"Walls",'Germany L1'!$S$2:$S$37,"<>")+COUNTIFS('Japan L7'!$B$2:$B$112,"Walls",'Japan L7'!$S$2:$S$112,"<>")+COUNTIFS('Snowden Tower L1'!$B$2:$B$86,"Walls",'Snowden Tower L1'!$S$2:$S$86,"<>")+COUNTIFS('Snowden Tower L2'!$B$2:$B$70,"Walls",'Snowden Tower L2'!$S$2:$S$70,"<>"))) -> 0.67065868 | K8: =COUNTIFS('Basic L1'!$B$2:$B$20,"Walls",'Basic L1'!$K$2:$K$20,">15")+COUNTIFS('Basic L2'!$B$2:$B$27,"Walls",'Basic L2'!$K$2:$K$27,">15")+COUNTIFS('Advanced L1'!$B$2:$B$78,"Walls",'Advanced L1'!$K$2:$K$78,">15")+COUNTIFS('Germany L1'!$B$2:$B$37,"Walls",'Germany L1'!$K$2:$K$37,">15")+COUNTIFS('Japan L7'!$B$2:$B$112,"Walls",'Japan L7'!$K$2:$K$112,">15")+COUNTIFS('Snowden Tower L1'!$B$2:$B$86,"Walls",'Snowden Tower L1'!$K$2:$K$86,">15")+COUNTIFS('Snowden Tower L2'!$B$2:$B$70,"Walls",'Snowden Tower L2'!$K$2:$K$70,">15") -> 0 | L8: 7.0315
